<?xml version="1.0"?>
<robot name="seven_dof_arm" xmlns:xacro="http://www.ros.org/wiki/xacro">

  <link name="world" type="fixed"/>
    <joint name="fixed" type="fixed">
    <parent link="world"/>
    <child link="base_link"/>
    <origin rpy="0 0 0" xyz="0 0 0"/>
    <!-- <xacro:insert_block name = "dorna_base_origin"/> -->
  </joint>
  <link
    name="base_link">
    <inertial>
      <origin
        xyz="0.0347002303371341 0.346023339775448 -0.0241867339220317"
        rpy="0 0 0" />
      <mass
        value="0.18575737424898" />
      <inertia
        ixx="0.0016866174407422"
        ixy="3.07155155497949E-09"
        ixz="1.91791459670807E-10"
        iyy="3.87750802818281E-05"
        iyz="-4.08545352649858E-09"
        izz="0.00170031937070701" />
    </inertial>
    <visual>
      <origin
        xyz="0 0 0"
        rpy="0 0 0" />
      <geometry>
        <mesh
          filename="package://seven_dof_arm/meshes/base_link.STL" />
      </geometry>
      <material
        name="">
        <color
          rgba="0.749019607843137 0.749019607843137 0.749019607843137 1" />
      </material>
    </visual>
    <collision>
      <origin
        xyz="0 0 0"
        rpy="0 0 0" />
      <geometry>
        <mesh
          filename="package://seven_dof_arm/meshes/base_link.STL" />
      </geometry>
    </collision>
  </link>
    <gazebo reference="base_link">
        <material>Gazebo/silver</material>
    </gazebo>
  <link
    name="link1">
    <inertial>
      <origin
        xyz="0.0916699629769903 -0.0442131895737334 -0.0674770407988403"
        rpy="0 0 0" />
      <mass
        value="0.435483637323834" />
      <inertia
        ixx="0.000554861160419143"
        ixy="-1.69557318491907E-06"
        ixz="1.10985030305624E-06"
        iyy="0.00067334192058171"
        iyz="5.78646055724129E-05"
        izz="0.000786642437899407" />
    </inertial>
    <visual>
      <origin
        xyz="0 0 0"
        rpy="0 0 0" />
      <geometry>
        <mesh
          filename="package://seven_dof_arm/meshes2/link1.STL" />
      </geometry>
      <material
        name="">
        <color
          rgba="0.792156862745098 0.819607843137255 0.933333333333333 1" />
      </material>
    </visual>
    <collision>
      <origin
        xyz="0 0 0"
        rpy="0 0 0" />
      <geometry>
        <mesh
          filename="package://seven_dof_arm/meshes2/link1.STL" />
      </geometry>
    </collision>
  </link>
    <gazebo reference="link1">
        <material>Gazebo/silver</material>
    </gazebo>
  <joint
    name="joint1"
    type="prismatic">
    <origin
      xyz="0.079186 -0.036824 0.45915"
      rpy="3.1416 0 1.5708" />
    <parent
      link="base_link" />
    <child
      link="link1" />
    <axis
      xyz="0 0 1" />
    <limit
      lower="0"
      upper="0.3"
      effort="0"
      velocity="0" />
  </joint>
  <link
    name="link2">
    <inertial>
      <origin
        xyz="-0.0362242257746984 0.00610793662936298 -4.5353654753888E-05"
        rpy="0 0 0" />
      <mass
        value="0.0692232619946469" />
      <inertia
        ixx="2.30301654770882E-05"
        ixy="-3.32021307521991E-12"
        ixz="9.55728406837182E-12"
        iyy="1.60035358829875E-05"
        iyz="3.10360859630282E-08"
        izz="1.67020019173866E-05" />
    </inertial>
    <visual>
      <origin
        xyz="0 0 0"
        rpy="0 0 0" />
      <geometry>
        <mesh
          filename="package://seven_dof_arm/meshes2/link2.STL" />
      </geometry>
      <material
        name="">
        <color
          rgba="0.792156862745098 0.819607843137255 0.933333333333333 1" />
      </material>
    </visual>
    <collision>
      <origin
        xyz="0 0 0"
        rpy="0 0 0" />
      <geometry>
        <mesh
          filename="package://seven_dof_arm/meshes2/link2.STL" />
      </geometry>
    </collision>
  </link>
  <gazebo reference="link2">
      <material>Gazebo/silver</material>
  </gazebo>
  <joint
    name="joint2"
    type="revolute">
    <origin
      xyz="0 -0.0083 -0.067713"
      rpy="-0.0070619 0 1.5708" />
    <parent
      link="link1" />
    <child
      link="link2" />
    <axis
      xyz="1 0 0" />
    <limit
      lower="-1.5702"
      upper="0.05236"
      effort="0"
      velocity="0" />
  </joint>
  <link
    name="link3">
    <inertial>
      <origin
        xyz="-0.0144850998690551 0.0559446704580446 -0.00595975002120575"
        rpy="0 0 0" />
      <mass
        value="0.256407451082195" />
      <inertia
        ixx="0.000181490660126937"
        ixy="1.73315158687538E-06"
        ixz="1.25188642393082E-05"
        iyy="0.000203552436340242"
        iyz="-1.76484174404525E-06"
        izz="0.000178856893048134" />
    </inertial>
    <visual>
      <origin
        xyz="0 0 0"
        rpy="0 0 0" />
      <geometry>
        <mesh
          filename="package://seven_dof_arm/meshes2/link3.STL" />
      </geometry>
      <material
        name="">
        <color
          rgba="0.792156862745098 0.819607843137255 0.933333333333333 1" />
      </material>
    </visual>
    <collision>
      <origin
        xyz="0 0 0"
        rpy="0 0 0" />
      <geometry>
        <mesh
          filename="package://seven_dof_arm/meshes2/link3.STL" />
      </geometry>
    </collision>
  </link>
  <gazebo reference="link3">
      <material>Gazebo/silver</material>
  </gazebo>
  <joint
    name="joint3"
    type="revolute">
    <origin
      xyz="-0.036224 0.0098864 -0.00015396"
      rpy="0 0.78602 0" />
    <parent
      link="link2" />
    <child
      link="link3" />
    <axis
      xyz="0 1 0" />
    <limit
      lower="-1.5702"
      upper="1.5702"
      effort="0"
      velocity="0" />
  </joint>
  <link
    name="link4">
    <inertial>
      <origin
        xyz="-0.109170138525759 -0.00125414996636081 -3.82551769230605E-05"
        rpy="0 0 0" />
      <mass
        value="0.307213644543192" />
      <inertia
        ixx="0.000100181559494598"
        ixy="1.48016719615696E-08"
        ixz="-2.6930022984696E-07"
        iyy="0.000601480975551128"
        iyz="2.36788719456859E-10"
        izz="0.000556821791320744" />
    </inertial>
    <visual>
      <origin
        xyz="0 0 0"
        rpy="0 0 0" />
      <geometry>
        <mesh
          filename="package://seven_dof_arm/meshes2/link4.STL" />
      </geometry>
      <material
        name="">
        <color
          rgba="1 1 1 1" />
      </material>
    </visual>
    <collision>
      <origin
        xyz="0 0 0"
        rpy="0 0 0" />
      <geometry>
        <mesh
          filename="package://seven_dof_arm/meshes2/link4.STL" />
      </geometry>
    </collision>
  </link>
  <gazebo reference="link4">
      <material>Gazebo/silver</material>
  </gazebo>
  <joint
    name="joint4"
    type="revolute">
    <origin
      xyz="0 0.060688 0"
      rpy="-3.1416 0.78477 0" />
    <parent
      link="link3" />
    <child
      link="link4" />
    <axis
      xyz="1 0 0" />
    <limit
      lower="0"
      upper="0.872665"
      effort="0"
      velocity="0" />
  </joint>
  <link
    name="link5">
    <inertial>
      <origin
        xyz="-4.03053779962151E-05 0.00226785503086656 0.000188099816106901"
        rpy="0 0 0" />
      <mass
        value="0.0783880463610158" />
      <inertia
        ixx="1.98092122009332E-05"
        ixy="-4.85880932081893E-09"
        ixz="8.53128675466692E-09"
        iyy="1.68289094477428E-05"
        iyz="3.70335541134835E-07"
        izz="2.75893747032841E-05" />
    </inertial>
    <visual>
      <origin
        xyz="0 0 0"
        rpy="0 0 0" />
      <geometry>
        <mesh
          filename="package://seven_dof_arm/meshes2/link5.STL" />
      </geometry>
      <material
        name="">
        <color
          rgba="0.792156862745098 0.819607843137255 0.933333333333333 1" />
      </material>
    </visual>
    <collision>
      <origin
        xyz="0 0 0"
        rpy="0 0 0" />
      <geometry>
        <mesh
          filename="package://seven_dof_arm/meshes2/link5.STL" />
      </geometry>
    </collision>
  </link>
  <gazebo reference="link5">
      <material>Gazebo/silver</material>
  </gazebo>
  <joint
    name="joint5"
    type="revolute">
    <origin
      xyz="-0.2417 0 0"
      rpy="3.1416 1.5708 0" />
    <parent
      link="link4" />
    <child
      link="link5" />
    <axis
      xyz="0 1 0" />
    <limit
      lower="0"
      upper="2.0944"
      effort="0"
      velocity="0" />
  </joint>
  <link
    name="link6">
    <inertial>
      <origin
        xyz="-1.71210129407129E-11 2.14186959673901E-06 0.0723884833771878"
        rpy="0 0 0" />
      <mass
        value="0.201176904931269" />
      <inertia
        ixx="0.000341739374396861"
        ixy="6.00880706868641E-10"
        ixz="3.83549654144875E-14"
        iyy="0.000337564433731988"
        iyz="1.35703929148043E-09"
        izz="4.87496416134206E-05" />
    </inertial>
    <visual>
      <origin
        xyz="0 0 0"
        rpy="0 0 0" />
      <geometry>
        <mesh
          filename="package://seven_dof_arm/meshes2/link6.STL" />
      </geometry>
      <material
        name="">
        <color
          rgba="0.792156862745098 0.819607843137255 0.933333333333333 1" />
      </material>
    </visual>
    <collision>
      <origin
        xyz="0 0 0"
        rpy="0 0 0" />
      <geometry>
        <mesh
          filename="package://seven_dof_arm/meshes2/link6.STL" />
      </geometry>
    </collision>
  </link>
  <gazebo reference="link6">
      <material>Gazebo/silver</material>
  </gazebo>
  <joint
    name="joint6"
    type="revolute">
    <origin
      xyz="0 0 0.023439"
      rpy="0 0 -1.5708" />
    <parent
      link="link5" />
    <child
      link="link6" />
    <axis
      xyz="0 0 1" />
    <limit
      lower="0"
      upper="6.2832"
      effort="0"
      velocity="0" />
  </joint>
  <link
    name="link7">
    <inertial>
      <origin
        xyz="0.00031222685375841 -0.000327180590844703 0.0210790419598621"
        rpy="0 0 0" />
      <mass
        value="0.0531058037510222" />
      <inertia
        ixx="1.87781255142653E-05"
        ixy="-2.13672586806955E-06"
        ixz="1.09897769756693E-07"
        iyy="2.87631837946065E-05"
        iyz="-6.51839344046795E-08"
        izz="4.1335700567351E-05" />
    </inertial>
    <visual>
      <origin
        xyz="0 0 0"
        rpy="0 0 0" />
      <geometry>
        <mesh
          filename="package://seven_dof_arm/meshes2/link7.STL" />
      </geometry>
      <material
        name="">
        <color
          rgba="0.792156862745098 0.819607843137255 0.933333333333333 1" />
      </material>
    </visual>
    <collision>
      <origin
        xyz="0 0 0"
        rpy="0 0 0" />
      <geometry>
        <mesh
          filename="package://seven_dof_arm/meshes2/link7.STL" />
      </geometry>
    </collision>
  </link>
  <gazebo reference="link7">
      <material>Gazebo/silver</material>
  </gazebo>
  <joint
    name="joint7"
    type="fixed">
    <origin
      xyz="0 0 0.14004"
      rpy="0 0 2.9385" />
    <parent
      link="link6" />
    <child
      link="link7" />
    <axis
      xyz="0 0 1" />
  </joint>
  <link
    name="linkf1">
    <inertial>
      <origin
        xyz="0.00314018004474953 -0.000769390443373714 -0.00966523365538721"
        rpy="0 0 0" />
      <mass
        value="0.0092906601057542" />
      <inertia
        ixx="1.34161161828399E-06"
        ixy="5.47668679324216E-08"
        ixz="-8.62150034576989E-08"
        iyy="1.50413012428117E-06"
        iyz="-7.65501105050382E-09"
        izz="5.35661234191757E-07" />
    </inertial>
    <visual>
      <origin
        xyz="0 0 0"
        rpy="0 0 0" />
      <geometry>
        <mesh
          filename="package://seven_dof_arm/meshes2/linkf1.STL" />
      </geometry>
      <material
        name="">
        <color
          rgba="0.792156862745098 0.819607843137255 0.933333333333333 1" />
      </material>
    </visual>
    <collision>
      <origin
        xyz="0 0 0"
        rpy="0 0 0" />
      <geometry>
        <mesh
          filename="package://seven_dof_arm/meshes2/linkf1.STL" />
      </geometry>
    </collision>
  </link>
  <gazebo reference="linkf1">
      <material>Gazebo/silver</material>
  </gazebo>
  <joint
    name="jointf1"
    type="prismatic">
    <origin
      xyz="0.021208 0.0009582 0.053493"
      rpy="-3.1241 0 0.20309" />
    <parent
      link="link7" />
    <child
      link="linkf1" />
    <axis
      xyz="-1 0 0" />
    <limit
      lower="0"
      upper="0.023"
      effort="0"
      velocity="0" />
  </joint>
  <link
    name="linkf2">
    <inertial>
      <origin
        xyz="0.00314018001393025 -0.000769390464555986 -0.00966523362529868"
        rpy="0 0 0" />
      <mass
        value="0.00929066004928656" />
      <inertia
        ixx="1.34161159681315E-06"
        ixy="5.47668657804483E-08"
        ixz="-8.62150024421522E-08"
        iyy="1.50413010518885E-06"
        iyz="-7.65500747497169E-09"
        izz="5.35661233459468E-07" />
    </inertial>
    <visual>
      <origin
        xyz="0 0 0"
        rpy="0 0 0" />
      <geometry>
        <mesh
          filename="package://seven_dof_arm/meshes2/linkf2.STL" />
      </geometry>
      <material
        name="">
        <color
          rgba="0.792156862745098 0.819607843137255 0.933333333333333 1" />
      </material>
    </visual>
    <collision>
      <origin
        xyz="0 0 0"
        rpy="0 0 0" />
      <geometry>
        <mesh
          filename="package://seven_dof_arm/meshes2/linkf2.STL" />
      </geometry>
    </collision>
  </link>
  <gazebo reference="linkf2">
      <material>Gazebo/silver</material>
  </gazebo>
  <joint
    name="jointf2"
    type="prismatic">
    <origin
      xyz="-0.0217 -0.0019765 0.053593"
      rpy="3.1241 0 -2.9385" />
    <parent
      link="link7" />
    <child
      link="linkf2" />
    <axis
      xyz="1 0 0" />
    <limit
      lower="-0.023"
      upper="0"
      effort="0"
      velocity="0" />
  </joint>
  <!-- <ros2_control name="GazeboSystem" type="system">
    <hardware>
      <plugin>gazebo_ros2_control/GazeboSystem</plugin>
    </hardware>
    <joint name="joint1">
      <command_interface name="position"/>
      <state_interface name="position">
        <param name="initial_value">0.0</param>
      </state_interface>
      <state_interface name="velocity"/>
      </joint>
    <joint name="joint2"> 
      <command_interface name="position"/>
      <state_interface name="position">
        <param name="initial_value">0.0</param>
      </state_interface>
      <state_interface name="velocity"/>
      </joint>
    <joint name="joint3">
      <command_interface name="position"/>
      <state_interface name="position">
        <param name="initial_value">0.0</param>
      </state_interface>
      <state_interface name="velocity"/>
      </joint>
    <joint name="joint4">
      <command_interface name="position"/>
      <state_interface name="position">
        <param name="initial_value">0.0</param>
      </state_interface>
      <state_interface name="velocity"/>
      </joint>
    <joint name="joint5">
      <command_interface name="position"/>
      <state_interface name="position">
        <param name="initial_value">0.0</param>
      </state_interface>
      <state_interface name="velocity"/>
      </joint>
    <joint name="joint6">
      <command_interface name="position"/>
      <state_interface name="position">
        <param name="initial_value">0.0</param>
      </state_interface>
      <state_interface name="velocity"/>
      </joint>
    <joint name="jointf1">
      <command_interface name="position"/>
      <state_interface name="position">
        <param name="initial_value">0.0</param>
      </state_interface>
      </joint>
    <joint name="jointf2">
      <param name="mimic">jointf1</param>
      <param name="multiplier">-1</param>
      <command_interface name="position"/>
      <state_interface name="position">
        <param name="initial_value">0.0</param>
      </state_interface>
      <state_interface name="velocity"/>
      </joint>
  </ros2_control>
  <gazebo>
      <plugin name="gazebo_ros2_control" filename="libgazebo_ros2_control.so">
        <parameters>$(find seven_dof_arm)/config/arm_controllers.yaml</parameters>
      </plugin>
  </gazebo> -->
</robot>

